Workbook

Sheet Raw_Data
A1: Respondent_ID | B1: Q1_Role | C1: Q2_MainUse | D1: Q3_Visualisation | E1: Q4_TotalEvacTime | F1: Q4_PercentageEvacuated | G1: Q4_AvgWaitingCongestion | H1: Q4_ExitUsed | I1: Q4_AlgorithmRuntime | J1: Q4_NodesExplored | K1: Q4_RiskSafetyScore | L1: Q5_CreateOwnLayout | M1: Q6_PlaceHazards | N1: Q7_CompareStrategies | O1: Q8_AutoRecommendationUseful | P1: Q8_BestMeans | Q1: Q9_SimpleToolButtons | R1: Q9_ClearColourCoding | S1: Q9_LabelsTooltips | T1: Q9_ResetClearGrid | U1: Q9_SaveLoadScenarios | V1: Q9_ExampleScenarios | W1: Q9_GraphsTablesResults | X1: Q10_ConfusingOrDifficult | Y1: Q11_MostAppealingFeature
A2: 1 | B2: A-Level Computer Science Student | C2: Learning how pathfinding/routing algorithms work | D2: Both step-by-step and instant modes | E2: 1 | F2: 0 | G2: 1 | H2: 0 | I2: 0 | J2: 1 | K2: 0 | L2: 5 | M2: 4 | N2: 5 | O2: Yes | P2: Best balance of safety and speed | Q2: 1 | R2: 1 | S2: 0 | T2: 0 | U2: 0 | V2: 1 | W2: 0 | X2: Too many settings on screen at once. Also if the colours for walls, hazards, exits and people are too similar it would be hard to follow. | Y2: A comparison mode that shows how different algorithms behave differently on the same map.
A3: 2 | B3: A-Level Computer Science Student | C3: Comparing different evacuation strategies | D3: Step-by-step movement of people | E3: 0 | F3: 1 | G3: 1 | H3: 0 | I3: 0 | J3: 0 | K3: 1 | L3: 4 | M3: 5 | N3: 5 | O3: Yes | P3: Safest route | Q3: 0 | R3: 1 | S3: 1 | T3: 0 | U3: 0 | V3: 0 | W3: 1 | X3: It would be confusing if I could run a simulation without understanding what each algorithm is actually trying to optimise. | Y3: Short explanations of each algorithm in simple terms before running the simulation.
A4: 3 | B4: Teacher | C4: Learning how pathfinding/routing algorithms work | D4: Both step-by-step and instant modes | E4: 1 | F4: 0 | G4: 0 | H4: 0 | I4: 0 | J4: 1 | K4: 1 | L4: 4 | M4: 4 | N4: 5 | O4: Yes | P4: Best balance of safety and speed | Q4: 0 | R4: 0 | S4: 1 | T4: 0 | U4: 0 | V4: 1 | W4: 1 | X4: Too much technical detail without explanation would make it difficult for weaker students. It has to be visual and clear. | Y4: A teacher mode with ready-made classroom scenarios and expected observations.
A5: 4 | B5: A-Level Computer Science Student | C5: General curiosity / experimentation | D5: Both step-by-step and instant modes | E5: 1 | F5: 0 | G5: 1 | H5: 1 | I5: 0 | J5: 0 | K5: 0 | L5: 5 | M5: 5 | N5: 4 | O5: Yes | P5: Least congestion | Q5: 1 | R5: 0 | S5: 0 | T5: 1 | U5: 1 | V5: 0 | W5: 0 | X5: If building the map takes too long or is weird, I would probably stop using it. | Y5: Being able to save my own scenarios and test them again after making changes.
A6: 5 | B6: A-Level Computer Science Student | C6: Learn how evacuation planning is affected by hazards and congestion | D6: Step-by-step movement of people | E6: 0 | F6: 1 | G6: 1 | H6: 0 | I6: 0 | J6: 0 | K6: 1 | L6: 3 | M6: 5 | N6: 4 | O6: Yes | P6: Fastest evacuation | Q6: 0 | R6: 1 | S6: 0 | T6: 1 | U6: 0 | V6: 1 | W6: 0 | X6: If hazards aren't clearly shown or if it's hard to tell why people changed their route then the simulation wouldn't make much sense. | Y6: A replay feature so I can watch the simulation again and focus on different parts.
A7: 6 | B7: A-Level Computer Science Student | C7: Learning how pathfinding/routing algorithms work | D7: Instant final result only | E7: 1 | F7: 0 | G7: 0 | H7: 0 | I7: 1 | J7: 1 | K7: 0 | L7: 4 | M7: 3 | N7: 5 | O7: Yes | P7: Fastest evacuation | Q7: 1 | R7: 0 | S7: 1 | T7: 0 | U7: 0 | V7: 0 | W7: 1 | X7: It'd be annoying if the program ran too slowly or the animations take too long every time. | Y7: A side-by-side statistics panel comparing each algorithm after one click.
A8: 7 | B8: A-Level Computer Science Student | C8: Learn how evacuation planning is affected by hazards and congestion | D8: Both step-by-step and instant modes | E8: 0 | F8: 0 | G8: 1 | H8: 1 | I8: 0 | J8: 0 | K8: 1 | L8: 5 | M8: 5 | N8: 4 | O8: Unsure | Q8: 0 | R8: 1 | S8: 0 | T8: 0 | U8: 1 | V8: 1 | W8: 0 | X8: I'd be confused if there were no guide as to what the numbers mean, like risk scores or algorithm statistics. | Y8: Hover-over explanations of results.
A9: 8 | B9: A-Level Computer Science Student | C9: Comparing different evacuation strategies | D9: Step-by-step movement of people | E9: 1 | F9: 0 | G9: 1 | H9: 1 | I9: 0 | J9: 0 | K9: 0 | L9: 4 | M9: 4 | N9: 5 | O9: Yes | P9: Least congestion | Q9: 1 | R9: 1 | S9: 0 | T9: 1 | U9: 0 | V9: 0 | W9: 0 | X9: If lots of people overlap visually or move too fast to follow, it'd be hard to learn anything from it. | Y9: The ability to slow down or speed up the simulation.
A10: 9 | B10: A-Level Computer Science Student | C10: Learning how pathfinding/routing algorithms work | D10: Both step-by-step and instant modes | E10: 1 | F10: 0 | G10: 0 | H10: 0 | I10: 1 | J10: 1 | K10: 0 | L10: 4 | M10: 4 | N10: 5 | O10: Yes | P10: Best balance of safety and speed | Q10: 0 | R10: 0 | S10: 1 | T10: 0 | U10: 0 | V10: 1 | W10: 1 | X10: If the simulator uses a lot of advanced terms without explaining them, it'd be difficult to understand or learn. | Y10: A built-in explanation panel that links to what happens in the simulation to exam topics.
A11: 10 | B11: A-Level Computer Science Student | C11: Learn how evacuation planning is affected by hazards and congestion | D11: Both step-by-step and instant modes | E11: 1 | F11: 0 | G11: 0 | H11: 1 | I11: 0 | J11: 0 | K11: 1 | L11: 5 | M11: 4 | N11: 5 | O11: Yes | P11: Safest route | Q11: 0 | R11: 1 | S11: 1 | T11: 0 | U11: 0 | V11: 1 | W11: 0 | X11: No explanation to data or why an algorithm chose a path would be confusing. | Y11: A feature that explains why one route was chosen over another.

Sheet Analysis
A1: Total respondents | B1: =COUNTA(tblResponses[Respondent_ID]) -> 10
A2: Q8 Part 1 Yes | B2: =COUNTIF(tblResponses[Q8_AutoRecommendationUseful],"Yes") -> 9
A4: Q1 Role | B4: Count | C4: %
A5: A-Level Computer Science Student | B5: =COUNTIF(tblResponses[Q1_Role],A5) -> 9 | C5: =B5/$B$1 -> 0.9
A6: Student interested in engineering / architecture / building design | B6: =COUNTIF(tblResponses[Q1_Role],A6) -> 0 | C6: =B6/$B$1 -> 0
A7: Teacher | B7: =COUNTIF(tblResponses[Q1_Role],A7) -> 1 | C7: =B7/$B$1 -> 0.1
A8: Other | B8: =COUNTIF(tblResponses[Q1_Role],A8) -> 0 | C8: =B8/$B$1 -> 0
A10: Q2 Main Use | B10: Count | C10: %
A11: Learning how pathfinding/routing algorithms work | B11: =COUNTIF(tblResponses[Q2_MainUse],A11) -> 4 | C11: =B11/$B$1 -> 0.4
A12: Learn how evacuation planning is affected by hazards and congestion | B12: =COUNTIF(tblResponses[Q2_MainUse],A12) -> 3 | C12: =B12/$B$1 -> 0.3
A13: Comparing different evacuation strategies | B13: =COUNTIF(tblResponses[Q2_MainUse],A13) -> 2 | C13: =B13/$B$1 -> 0.2
A14: General curiosity / experimentation | B14: =COUNTIF(tblResponses[Q2_MainUse],A14) -> 1 | C14: =B14/$B$1 -> 0.1
A15: Other | B15: =COUNTIF(tblResponses[Q2_MainUse],A15) -> 0 | C15: =B15/$B$1 -> 0
A17: Q3 Visualisation | B17: Count | C17: %
A18: Step-by-step movement of people | B18: =COUNTIF(tblResponses[Q3_Visualisation],A18) -> 3 | C18: =B18/$B$1 -> 0.3
A19: Instant final result only | B19: =COUNTIF(tblResponses[Q3_Visualisation],A19) -> 1 | C19: =B19/$B$1 -> 0.1
A20: Both step-by-step and instant modes | B20: =COUNTIF(tblResponses[Q3_Visualisation],A20) -> 6 | C20: =B20/$B$1 -> 0.6
A21: Not sure | B21: =COUNTIF(tblResponses[Q3_Visualisation],A21) -> 0 | C21: =B21/$B$1 -> 0
A23: Q8 Auto Recommendation Useful | B23: Count | C23: %
A24: Yes | B24: =COUNTIF(tblResponses[Q8_AutoRecommendationUseful],A24) -> 9 | C24: =B24/$B$1 -> 0.9
A25: No | B25: =COUNTIF(tblResponses[Q8_AutoRecommendationUseful],A25) -> 0 | C25: =B25/$B$1 -> 0
A26: Unsure | B26: =COUNTIF(tblResponses[Q8_AutoRecommendationUseful],A26) -> 1 | C26: =B26/$B$1 -> 0.1
A28: Q4 Useful Outputs | B28: Count | C28: %
A29: Total evacuation time | B29: =SUM(tblResponses[Q4_TotalEvacTime]) -> 7 | C29: =B29/$B$1 -> 0.7
A30: Percentage evacuated | B30: =SUM(tblResponses[Q4_PercentageEvacuated]) -> 2 | C30: =B30/$B$1 -> 0.2
A31: Average waiting time / congestion | B31: =SUM(tblResponses[Q4_AvgWaitingCongestion]) -> 6 | C31: =B31/$B$1 -> 0.6
A32: Which exit people used | B32: =SUM(tblResponses[Q4_ExitUsed]) -> 4 | C32: =B32/$B$1 -> 0.4
A33: Algorithm runtime | B33: =SUM(tblResponses[Q4_AlgorithmRuntime]) -> 2 | C33: =B33/$B$1 -> 0.2
A34: Number of nodes explored | B34: =SUM(tblResponses[Q4_NodesExplored]) -> 4 | C34: =B34/$B$1 -> 0.4
A35: Risk/safety score | B35: =SUM(tblResponses[Q4_RiskSafetyScore]) -> 5 | C35: =B35/$B$1 -> 0.5
A37: Q5 Create Own Layout | B37: Count | C37: %
A38: 1 | B38: =COUNTIF(tblResponses[Q5_CreateOwnLayout],A38) -> 0 | C38: =B38/$B$1 -> 0
A39: 2 | B39: =COUNTIF(tblResponses[Q5_CreateOwnLayout],A39) -> 0 | C39: =B39/$B$1 -> 0
A40: 3 | B40: =COUNTIF(tblResponses[Q5_CreateOwnLayout],A40) -> 1 | C40: =B40/$B$1 -> 0.1
A41: 4 | B41: =COUNTIF(tblResponses[Q5_CreateOwnLayout],A41) -> 5 | C41: =B41/$B$1 -> 0.5
A42: 5 | B42: =COUNTIF(tblResponses[Q5_CreateOwnLayout],A42) -> 4 | C42: =B42/$B$1 -> 0.4
A43: Average | B43: =AVERAGE(tblResponses[Q5_CreateOwnLayout]) -> 4.3
A44: Median | B44: =MEDIAN(tblResponses[Q5_CreateOwnLayout]) -> 4
A46: Q6 Place Hazards | B46: Count | C46: %
A47: 1 | B47: =COUNTIF(tblResponses[Q6_PlaceHazards],A47) -> 0 | C47: =B47/$B$1 -> 0
...

Sheet Charts

Sheet Themes
A1: Respondent_ID | B1: Q10_NeedExplanations | C1: Q10_VisualClarity | D1: Q10_TooComplex | E1: Q10_SlowOrTricky | F1: Q11_AlgorithmComparison | G1: Q11_ExplanationFeature | H1: Q11_SaveReplay | I1: Q11_ExampleScenarios
A2: 1 | B2: 0 | C2: 1 | D2: 0 | E2: 0 | F2: 1 | G2: 0 | H2: 0 | I2: 0
A3: 2 | B3: 1 | C3: 0 | D3: 1 | E3: 0 | F3: 1 | G3: 1 | H3: 0 | I3: 0
A4: 3 | B4: 1 | C4: 1 | D4: 0 | E4: 0 | F4: 0 | G4: 0 | H4: 0 | I4: 1
A5: 4 | B5: 0 | C5: 0 | D5: 0 | E5: 1 | F5: 0 | G5: 0 | H5: 1 | I5: 0
A6: 5 | B6: 0 | C6: 1 | D6: 0 | E6: 0 | F6: 0 | G6: 0 | H6: 1 | I6: 0
A7: 6 | B7: 0 | C7: 0 | D7: 0 | E7: 1 | F7: 1 | G7: 1 | H7: 0 | I7: 0
A8: 7 | B8: 1 | C8: 0 | D8: 0 | E8: 0 | F8: 0 | G8: 1 | H8: 0 | I8: 0
A9: 8 | B9: 0 | C9: 1 | D9: 0 | E9: 0 | F9: 0 | G9: 1 | H9: 0 | I9: 0
A10: 9 | B10: 1 | C10: 0 | D10: 1 | E10: 0 | F10: 0 | G10: 1 | H10: 0 | I10: 0
A11: 10 | B11: 1 | C11: 0 | D11: 0 | E11: 0 | F11: 0 | G11: 1 | H11: 0 | I11: 0
A12: Sum | B12: =SUM(B$2:B$11) -> 5 | C12: =SUM(C$2:C$11) -> 4 | D12: =SUM(D$2:D$11) -> 2 | E12: =SUM(E$2:E$11) -> 2 | F12: =SUM(F$2:F$11) -> 3 | G12: =SUM(G$2:G$11) -> 6 | H12: =SUM(H$2:H$11) -> 2 | I12: =SUM(I$2:I$11) -> 1
A13: % | B13: =B$12/Analysis!$B$1 -> 0.5 | C13: =C$12/Analysis!$B$1 -> 0.4 | D13: =D$12/Analysis!$B$1 -> 0.2 | E13: =E$12/Analysis!$B$1 -> 0.2 | F13: =F$12/Analysis!$B$1 -> 0.3 | G13: =G$12/Analysis!$B$1 -> 0.6 | H13: =H$12/Analysis!$B$1 -> 0.2 | I13: =I$12/Analysis!$B$1 -> 0.1

Sheet Lists
A1: A-Level Computer Science Student | B1: Learning how pathfinding/routing algorithms work | C1: Step-by-step movement of people | D1: Yes | E1: Fastest evacuation
A2: Student interested in engineering / architecture / building design | B2: Learn how evacuation planning is affected by hazards and congestion | C2: Instant final result only | D2: No | E2: Safest route
A3: Teacher | B3: Comparing different evacuation strategies | C3: Both step-by-step and instant modes | D3: Unsure | E3: Best balance of safety and speed
A4: Other | B4: General curiosity / experimentation | C4: Not sure | E4: Least congestion
B5: Other | E5: Other
